'use client';

import React from 'react';
import { Button } from '@/components/ui/button';
import { AlertTriangle, RefreshCw } from 'lucide-react';

interface ErrorBoundaryState {
  hasError: boolean;
  error?: Error;
  errorInfo?: React.ErrorInfo;
}

interface ErrorBoundaryProps {
  children: React.ReactNode;
  fallback?: React.ComponentType<ErrorFallbackProps>;
  onError?: (error: Error, errorInfo: React.ErrorInfo) => void;
}

interface ErrorFallbackProps {
  error: Error;
  resetError: () => void;
}

/**
 * Default error fallback component
 */
function DefaultErrorFallback({ error, resetError }: ErrorFallbackProps) {
  return (
    <div className="flex min-h-[400px] flex-col items-center justify-center space-y-4 p-8 text-center">
      <AlertTriangle className="h-12 w-12 text-destructive" />
      <div className="space-y-2">
        <h2 className="text-xl font-semibold">Something went wrong</h2>
        <p className="text-sm text-muted-foreground max-w-md">
          We&apos;re sorry, but something unexpected happened. Please try refreshing the page.
        </p>
        {process.env.NODE_ENV === 'development' && (
          <details className="mt-4 text-left">
            <summary className="cursor-pointer text-sm font-medium">
              Error Details (Development)
            </summary>
            <pre className="mt-2 whitespace-pre-wrap text-xs text-red-600 bg-red-50 p-2 rounded">
              {error.message}
              {error.stack}
            </pre>
          </details>
        )}
      </div>
      <Button onClick={resetError} className="mt-4">
        <RefreshCw className="mr-2 h-4 w-4" />
        Try Again
      </Button>
    </div>
  );
}

/**
 * React Error Boundary component
 * 
 * Catches JavaScript errors anywhere in the child component tree,
 * logs those errors, and displays a fallback UI instead of crashing.
 */
export class ErrorBoundary extends React.Component<ErrorBoundaryProps, ErrorBoundaryState> {
  constructor(props: ErrorBoundaryProps) {
    super(props);
    this.state = { hasError: false };
  }

  static getDerivedStateFromError(error: Error): ErrorBoundaryState {
    return {
      hasError: true,
      error,
    };
  }

  componentDidCatch(error: Error, errorInfo: React.ErrorInfo) {
    console.error('Error Boundary caught an error:', error, errorInfo);
    
    // Call optional error handler
    if (this.props.onError) {
      this.props.onError(error, errorInfo);
    }

    // Store error info in state for debugging
    this.setState({
      error,
      errorInfo,
    });
  }

  resetError = () => {
    this.setState({ hasError: false, error: undefined, errorInfo: undefined });
  };

  render() {
    if (this.state.hasError && this.state.error) {
      const FallbackComponent = this.props.fallback || DefaultErrorFallback;
      
      return (
        <FallbackComponent 
          error={this.state.error} 
          resetError={this.resetError} 
        />
      );
    }

    return this.props.children;
  }
}

/**
 * HOC to wrap components with error boundary
 */
export function withErrorBoundary<P extends object>(
  Component: React.ComponentType<P>,
  errorBoundaryProps?: Omit<ErrorBoundaryProps, 'children'>
) {
  const WrappedComponent = (props: P) => (
    <ErrorBoundary {...errorBoundaryProps}>
      <Component {...props} />
    </ErrorBoundary>
  );
  
  WrappedComponent.displayName = `withErrorBoundary(${Component.displayName || Component.name})`;
  
  return WrappedComponent;
}

/**
 * Hook to manually trigger error boundary (useful for async errors)
 */
export function useErrorBoundary() {
  const [, setState] = React.useState();
  
  return React.useCallback((error: Error) => {
    setState(() => {
      throw error;
    });
  }, []);
}